Workbook

Sheet Dashboard
C3: To make a copy go to file > make a copy | G3: DM Sorcery Metric Dashboard | J3: This dashboard does not require manual inputs!
C7: (Platform) | D7: Jan | E7: Feb | F7: Mar | G7: Apr | H7: May | I7: Jun | J7: Jul | K7: Aug | L7: Sep | M7: Oct | N7: Nov | O7: Dec | P7: Totals
C8: Initiated (A) | D8: =Jan!D5 -> 506 | E8: =Feb!D5 -> 409 | F8: =Mar!D5 -> 686 | G8: =Apr!D5 -> 712 | H8: =May!D5 -> 0 | I8: =Jun!D5 -> 0 | J8: =Jul!D5 -> 0 | K8: =Aug!D5 -> 0 | L8: =Sep!D5 -> 0 | M8: =Oct!D5 -> 0 | N8: =Nov!D5 -> 0 | O8: =Dec!D5 -> 0 | P8: =sum(D8:O8) -> 2313
C9: Media Seen (MS) | D9: =Jan!D6 -> 312 | E9: =Feb!D6 -> 11 | F9: =Mar!D6 -> 0 | G9: =Apr!D6 -> 0 | H9: =May!D6 -> 0 | I9: =Jun!D6 -> 0 | J9: =Jul!D6 -> 0 | K9: =Aug!D6 -> 0 | L9: =Sep!D6 -> 0 | M9: =Oct!D6 -> 0 | N9: =Nov!D6 -> 0 | O9: =Dec!D6 -> 0 | P9: =sum(D9:O9) -> 323
C10: Engaged (B) | D10: =Jan!D7 -> 76 | E10: =Feb!D7 -> 55 | F10: =Mar!D7 -> 83 | G10: =Apr!D7 -> 83 | H10: =May!D7 -> 0 | I10: =Jun!D7 -> 0 | J10: =Jul!D7 -> 0 | K10: =Aug!D7 -> 0 | L10: =Sep!D7 -> 0 | M10: =Oct!D7 -> 0 | N10: =Nov!D7 -> 0 | O10: =Dec!D7 -> 0 | P10: =sum(D10:O10) -> 297
C11: Calendly'd (C) | D11: =Jan!D8 -> 22 | E11: =Feb!D8 -> 16 | F11: =Mar!D8 -> 35 | G11: =Apr!D8 -> 39 | H11: =May!D8 -> 0 | I11: =Jun!D8 -> 0 | J11: =Jul!D8 -> 0 | K11: =Aug!D8 -> 0 | L11: =Sep!D8 -> 0 | M11: =Oct!D8 -> 0 | N11: =Nov!D8 -> 0 | O11: =Dec!D8 -> 0 | P11: =sum(D11:O11) -> 112
C12: Booked (D) | D12: =Jan!D9 -> 17 | E12: =Feb!D9 -> 10 | F12: =Mar!D9 -> 24 | G12: =Apr!D9 -> 21 | H12: =May!D9 -> 0 | I12: =Jun!D9 -> 0 | J12: =Jul!D9 -> 0 | K12: =Aug!D9 -> 0 | L12: =Sep!D9 -> 0 | M12: =Oct!D9 -> 0 | N12: =Nov!D9 -> 0 | O12: =Dec!D9 -> 0 | P12: =sum(D12:O12) -> 72
C13: MSR | D13: =Jan!G5 -> 0.61660079 | E13: =Feb!G5 -> 0.026894866 | F13: =Mar!G5 -> 0 | G13: =Apr!G5 -> 0 | H13: =May!G5 -> #DIV/0! | I13: =Jun!G5 -> #DIV/0! | J13: =Jul!G5 -> #DIV/0! | K13: =Aug!G5 -> #DIV/0! | L13: =Sep!G5 -> #DIV/0! | M13: =Oct!G5 -> #DIV/0! | N13: =Nov!G5 -> #DIV/0! | O13: =Dec!G5 -> #DIV/0! | P13: =average(D13:O13) -> #DIV/0!
C14: PRR | D14: =Jan!G6 -> 0.15019763 | E14: =Feb!G6 -> 0.13447433 | F14: =Mar!G6 -> 0.12099125 | G14: =Apr!G6 -> 0.11657303 | H14: =May!G6 -> #DIV/0! | I14: =Jun!G6 -> #DIV/0! | J14: =Jul!G6 -> #DIV/0! | K14: =Aug!G6 -> #DIV/0! | L14: =Sep!G6 -> #DIV/0! | M14: =Oct!G6 -> #DIV/0! | N14: =Nov!G6 -> #DIV/0! | O14: =Dec!G6 -> #DIV/0! | P14: =average(D14:O14) -> #DIV/0!
C15: CSR | D15: =Jan!G7 -> 0.043478261 | E15: =Feb!G7 -> 0.039119804 | F15: =Mar!G7 -> 0.051020408 | G15: =Apr!G7 -> 0.054775281 | H15: =May!G7 -> #DIV/0! | I15: =Jun!G7 -> #DIV/0! | J15: =Jul!G7 -> #DIV/0! | K15: =Aug!G7 -> #DIV/0! | L15: =Sep!G7 -> #DIV/0! | M15: =Oct!G7 -> #DIV/0! | N15: =Nov!G7 -> #DIV/0! | O15: =Dec!G7 -> #DIV/0! | P15: =average(D15:O15) -> #DIV/0!
C16: ABR | D16: =Jan!G8 -> 0.033596838 | E16: =Feb!G8 -> 0.024449878 | F16: =Mar!G8 -> 0.034985423 | G16: =Apr!G8 -> 0.029494382 | H16: =May!G8 -> #DIV/0! | I16: =Jun!G8 -> #DIV/0! | J16: =Jul!G8 -> #DIV/0! | K16: =Aug!G8 -> #DIV/0! | L16: =Sep!G8 -> #DIV/0! | M16: =Oct!G8 -> #DIV/0! | N16: =Nov!G8 -> #DIV/0! | O16: =Dec!G8 -> #DIV/0! | P16: =average(D16:O16) -> #DIV/0!
C17: A > MS | D17: =Jan!J5 -> 0.61660079 | E17: =Feb!J5 -> 0.026894866 | F17: =Mar!J5 -> 0 | G17: =Apr!J5 -> 0 | H17: =May!J5 -> #DIV/0! | I17: =Jun!J5 -> #DIV/0! | J17: =Jul!J5 -> #DIV/0! | K17: =Aug!J5 -> #DIV/0! | L17: =Sep!J5 -> #DIV/0! | M17: =Oct!J5 -> #DIV/0! | N17: =Nov!J5 -> #DIV/0! | O17: =Dec!J5 -> #DIV/0! | P17: =average(D17:O17) -> #DIV/0!
C18: MS > B | D18: =Jan!J6 -> 0.24358974 | E18: =Feb!J6 -> 5 | F18: =Mar!J6 -> #DIV/0! | G18: =Apr!J6 -> #DIV/0! | H18: =May!J6 -> #DIV/0! | I18: =Jun!J6 -> #DIV/0! | J18: =Jul!J6 -> #DIV/0! | K18: =Aug!J6 -> #DIV/0! | L18: =Sep!J6 -> #DIV/0! | M18: =Oct!J6 -> #DIV/0! | N18: =Nov!J6 -> #DIV/0! | O18: =Dec!J6 -> #DIV/0! | P18: =average(D18:O18) -> #DIV/0!
C19: B > C | D19: =Jan!J7 -> 0.28947368 | E19: =Feb!J7 -> 0.29090909 | F19: =Mar!J7 -> 0.42168675 | G19: =Apr!J7 -> 0.46987952 | H19: =May!J7 -> #DIV/0! | I19: =Jun!J7 -> #DIV/0! | J19: =Jul!J7 -> #DIV/0! | K19: =Aug!J7 -> #DIV/0! | L19: =Sep!J7 -> #DIV/0! | M19: =Oct!J7 -> #DIV/0! | N19: =Nov!J7 -> #DIV/0! | O19: =Dec!J7 -> #DIV/0! | P19: =average(D19:O19) -> #DIV/0!
C20: C > D | D20: =Jan!J8 -> 0.77272727 | E20: =Feb!J8 -> 0.625 | F20: =Mar!J8 -> 0.68571429 | G20: =Apr!J8 -> 0.53846154 | H20: =May!J8 -> #DIV/0! | I20: =Jun!J8 -> #DIV/0! | J20: =Jul!J8 -> #DIV/0! | K20: =Aug!J8 -> #DIV/0! | L20: =Sep!J8 -> #DIV/0! | M20: =Oct!J8 -> #DIV/0! | N20: =Nov!J8 -> #DIV/0! | O20: =Dec!J8 -> #DIV/0! | P20: =average(D20:O20) -> #DIV/0!
C21: Requests | D21: =Jan!O6 | E21: =Feb!O6 | F21: =Mar!O6 | G21: =Apr!O6 | H21: =May!O6 | I21: =Jun!O6 | J21: =Jul!O6 | K21: =Aug!O6 | L21: =Sep!O6 | M21: =Oct!O6 | N21: =Nov!O6 | O21: =Dec!O6 | P21: =average(D21:O21) -> #DIV/0!
C22: Accepts | D22: =Jan!P6 | E22: =Feb!P6 | F22: =Mar!P6 | G22: =Apr!P6 | H22: =May!P6 | I22: =Jun!P6 | J22: =Jul!P6 | K22: =Aug!P6 | L22: =Sep!P6 | M22: =Oct!P6 | N22: =Nov!P6 | O22: =Dec!P6 | P22: =average(D22:O22) -> #DIV/0!
C23: CAR % | D23: =Jan!Q6 -> #DIV/0! | E23: =Feb!Q6 -> #DIV/0! | F23: =Mar!Q6 -> #DIV/0! | G23: =Apr!Q6 -> #DIV/0! | H23: =May!Q6 -> #DIV/0! | I23: =Jun!Q6 -> #DIV/0! | J23: =Jul!Q6 -> #DIV/0! | K23: =Aug!Q6 -> #DIV/0! | L23: =Sep!Q6 -> #DIV/0! | M23: =Oct!Q6 -> #DIV/0! | N23: =Nov!Q6 -> #DIV/0! | O23: =Dec!Q6 -> #DIV/0! | P23: =average(D23:O23) -> #DIV/0!
P24: Averages ^
B26: © Imperium Agency - All rights reserved. Do not share, copy, reproduce or sell any part of this document unless you have written permission from Imperium Labs LTD. All infringements will be prosecuted. If you are the personal owner of the Imperium Labs LTD End User License then you may use it for your own use but not for any other purpose.

Sheet Jan
B2: © Imperium Agency - All rights reserved. Do not share, copy, reproduce or sell any part of this document unless you have written permission from Imperium Labs LTD. All infringements will be prosecuted. If you are the personal owner of the Imperium Labs LTD End User License then you may use it for your own use but not for any other purpose.
C4: Stage | D4: Prospects | F4: Overall | G4: Conversion % | I4: Stage | J4: Conversion %
C5: (A) | D5: =COUNTIF(B13:B1000, "<>") -> 506 | F5: MSR | G5: =D6/D5 -> 0.61660079 | I5: A > MS | J5: =D6/D5 -> 0.61660079 | O5: Requests | P5: Accepted | Q5: CAR%
C6: (MS) | D6: =COUNTIF(K13:K1000, "YES") -> 312 | F6: PRR | G6: =D7/D5 -> 0.15019763 | I6: MS > B | J6: =D7/D6 -> 0.24358974 | Q6: =P6/O6 -> #DIV/0!
C7: (B) | D7: =COUNTIF(N13:N1000, "<>") -> 76 | F7: CSR | G7: =D8/D5 -> 0.043478261 | I7: B > C | J7: =D8/D7 -> 0.28947368
C8: (C) | D8: =COUNTIF(AB13:AB1000, "<>") -> 22 | F8: ABR | G8: =D9/D5 -> 0.033596838 | I8: C > D | J8: =D9/D8 -> 0.77272727
C9: (D) | D9: =COUNTIF(AP13:AP1000, "<>") -> 17
B11: To make a copy go file > make a copy
B12: Name (Initiate) (A) | C12: Profile Link | D12: Date Initiated | E12: 1A | F12: Notes | K12: Media Seen (MS) | N12: Name (Engaged) (B) | O12: Profile Link | P12: Date Engaged | Q12: 1B | R12: 2B | S12: 3B | T12: 4B | U12: 5B | V12: 6B | W12: 7B | X12: 8B | Y12: Notes | AB12: Name (C) | AC12: Profile Link | AD12: Date (C) | AE12: 1C | AF12: 2C | AG12: 3C | AH12: 4C | AI12: 5C | AJ12: 6C | AK12: 7C | AL12: 8B | AM12: Notes | AP12: Name (D) | AQ12: Date (D) | AR12: Notes
B13: Martin | C13: https://www.instagram.com/maartinn.73?igsh=MTFidm9yMjh2bXd4dA== | D13: 1,01 | E13: 02,1 | K13: YES | N13: Arnau | O13: https://www.instagram.com/arnauturner?igsh=MXZveDVsa3RteGlvag== | P13: 1,01 | Q13: 03,1 | R13: fup mar | AB13: Raul | AC13: https://www.instagram.com/raul_sansegundo?igsh=c2I5dncxNXZwZGVx | AD13: 05,1 | AE13: 07,1 | AF13: ni | AP13: build from within
B14: mercy | C14: https://www.instagram.com/mercyimagenymoda?igsh=cHVlMWlkaHFya2Z2 | D14: 1,01 | E14: 02,1 | K14: YES | N14: Mercy | O14: https://www.instagram.com/mercyimagenymoda?igsh=cHVlMWlkaHFya2Z2 | P14: 02,1 | Q14: 02,1 | R14: 03,1 | S14: 04,1 | T14: 07,1 | U14: 09,1 | AB14: build from within | AC14: https://www.instagram.com/buildfromwithin_bfw?igsh=MWJ5cWY4NWo0d2Z5ag== | AD14: 05,1 | AP14: Javier
B15: syd beat | C15: https://www.instagram.com/syd_beat?igsh=OTFuNzRpZm1ramQ3 | D15: 1,01 | E15: 02,1 | O15: https://www.instagram.com/kaimmakenoise?igsh=MWlwM3ZkYXpxdDJ6Mg== | P15: 01,1 | Q15: fup marzo | AB15: Javier | AC15: https://www.instagram.com/javier.botia?igsh=emc5NHVjemwwOG5z | AD15: 05,1 | AP15: marcelo
B16: chenaamado | C16: https://www.instagram.com/chenaamado?igsh=ODJreGxjOXBtdm5t | D16: 1,01 | E16: 02,1 | N16: hyrox trainer | O16: https://www.instagram.com/jmpfunxional?igsh=bjB5aWpiNnM0em8z | P16: 01,1 | Q16: 02,1 | R16: 03,1 | S16: 04,1 | T16: 07,1 | U16: 09,1 | AB16: marcelo | AC16: https://www.instagram.com/marceloperezsanders?igsh=aDQ1dWEwY3Btbjd1 | AD16: 07,1 | AP16: ismael babinou
B17: sr bitcoff | C17: https://www.instagram.com/sr.bitcooff?igsh=dmRxcnNsdzB4c3J1 | D17: 1,01 | E17: 02,1 | N17: dani | O17: https://www.instagram.com/dani.ssuarez?igsh=MTE1cGZzMHh5Z2Fsbg== | P17: 03,1 | Q17: 03,1 | R17: 04,1 | S17: 07,1 | T17: 09,1 | AB17: felix | AC17: https://www.instagram.com/felixpichardo.ff?igsh=MWNlcGdzcng3Z3luNw== | AD17: 10,1 | AP17: felix | AQ17: 12,1
B18: ja saavedra | C18: https://www.instagram.com/ja.saavedra?igsh=MXZqMHB3YXkzeHpteg== | D18: 1,01 | E18: 02,1 | N18: Marcelo | O18: https://www.instagram.com/marceloperezsanders?igsh=aDQ1dWEwY3Btbjd1 | P18: 02,1 | Q18: 05,1 | R18: 07,5 | AB18: ismael babinou | AC18: https://www.instagram.com/ismaelbabinoufit?igsh=NjcxMXZncjRqZ3k5 | AD18: 10,1 | AP18: Carmen | AQ18: 12,1
B19: kaim | C19: https://www.instagram.com/kaimmakenoise?igsh=MWlwM3ZkYXpxdDJ6Mg== | D19: 1,01 | E19: 02,1 | K19: YES | N19: despertando | O19: https://www.instagram.com/despertandolibertad?igsh=cXE0Y3FkNWJpYmNp | P19: 02,1 | Q19: 03,1 | R19: 04,1 | S19: 07,1 | T19: ni | AB19: Carmen | AC19: https://www.instagram.com/carmen.luna.creviz?igsh=NHJvczNjZWJtYTFn | AD19: 12,1 | AP19: Nat delagala | AQ19: 13,1
B20: matito | C20: https://www.instagram.com/matito0709?igsh=cXhjMGJjYzVoZHZx | D20: 1,01 | E20: 02,1 | K20: YES | N20: eloi | O20: https://www.instagram.com/eloiportela_?igsh=MW5naGNlZDhlbXNxeg== | P20: 02,1 | Q20: 03,1 | R20: 04,1 | S20: obj | T20: ni | AB20: milky | AC20: https://www.instagram.com/mikydata?igsh=MThvc3licnJ2ZXh6ZA== | AD20: 13,1 | AE20: Ni | AP20: Arnau | AQ20: 14,1
B21: fausto | C21: https://www.instagram.com/faustoreparaciones?igsh=cDNmMDQ0ZDR4dDgy | D21: 1,01 | E21: 02,1 | K21: YES | N21: yiri | O21: https://www.instagram.com/yiri_chaer?igsh=MTZsdHc1bG13bHdhbQ== | P21: 02,1 | Q21: 04,1 | R21: 07,1 | S21: 09,1 | AB21: andrea | AC21: https://www.instagram.com/soyandreacrea?igsh=aDh2OTk3dHBjZTV3 | AD21: 13,1 | AE21: 14,1 | AF21: 16,1 | AG21: 18,1 | AH21: 20,1 | AP21: Irene | AQ21: 15,1
B22: alejandro | C22: https://www.instagram.com/alejandro_sanchez995?igsh=MTF1Mm5hMmhjYWp2dA== | D22: 1,01 | E22: 02,1 | K22: YES | N22: Ferran | O22: https://www.instagram.com/ferran_lorenzo?igsh=eDFwODFzYWJ3Zmdq | P22: 02,1 | Q22: 04,1 | R22: 07,1 | S22: ni | AB22: nat delgada | AC22: https://www.instagram.com/nat.delagala?igsh=MXNyNW5vc2FhZXliNQ== | AD22: 13,1 | AP22: felipe | AQ22: 17,1
B23: matias | C23: https://www.instagram.com/matiaspicornell?igsh=b2g0YnNtcHJ1emRw | D23: 1,01 | E23: 02,1 | K23: YES | N23: renovacion femenina | O23: https://www.instagram.com/renovacion_femenina?igsh=dzI4bWJlbW53Y24= | P23: 02,1 | Q23: 04,1 | R23: 07,1 | S23: 09,1 | T23: 13,1 | U23: Fup 19 | V23: 20,1 | AB23: Arnau | AC23: https://www.instagram.com/arnauturner?igsh=MXZveDVsa3RteGlvag== | AD23: 14,1 | AP23: Luis ciprés | AQ23: 20,1
B24: deby | C24: https://www.instagram.com/deby8619?igsh=MTlsZTVnZzVyNXBkNA== | D24: 1,01 | E24: 02,1 | N24: Build from within | O24: https://www.instagram.com/buildfromwithin_bfw?igsh=MWJ5cWY4NWo0d2Z5ag== | P24: 03,1 | Q24: 05,1 | AB24: ionut | AC24: https://www.instagram.com/ionivo?igsh=MTVkdDVqaXE4anVkZg== | AD24: 16,1 | AE24: 17,1 | AF24: 20,1 | AG24: 22,1 | AH24: 26,1 | AI24: 27,2 | AP24: adrian | AQ24: 26,1
B25: kairos | C25: https://www.instagram.com/_.kaiiros?igsh=Z2s5ZWdjcWwzanZn | D25: 1,01 | E25: 02,1 | K25: YES | N25: nacho angel | O25: https://www.instagram.com/nachorangeel?igsh=bXYxd2E4aGJ4Y3F3 | P25: 04,1 | Q25: 05,1 | R25: 07,1 | S25: 09,1 | AB25: Felipe | AC25: https://www.instagram.com/felipecastilloworner?igsh=Nm0wa2E0cGMybDhl | AD25: 17,1 | AP25: ionut | AQ25: 28,1
B26: lidia lopez | C26: https://www.instagram.com/lidialopez.urbandog?igsh=MThpaXl5bG4ycnU1OQ== | D26: 1,01 | E26: 02,1 | F26: nq | K26: YES | N26: blanca | O26: https://www.instagram.com/blancavilanovai?igsh=aTRxMzMwNzczNWNi | P26: 04,1 | Q26: 05,1 | R26: 07,1 | S26: fup 20 enero | T26: 20,1 | U26: 21,1 | AB26: Manu | AC26: https://www.instagram.com/macnumania?igsh=ZjhzeDYzem1mbmpw | AD26: 20,1 | AE26: 26,1 | AF26: 28,1 | AG26: 30,1 | AH26: 01,2 | AP26: manu | AQ26: 02,2
B27: erick | C27: https://www.instagram.com/erick_sw_parkour?igsh=MTJqbXptbng3a2cwNg== | D27: 1,01 | E27: 02,1 | F27: nq | K27: YES | N27: poly anna | O27: https://www.instagram.com/poly_anna___?igsh=MWNkNmQ0djRmd2JxbA== | P27: 04,1 | Q27: 05,1 | R27: 08,1 | S27: 09,1 | T27: 13,1 | U27: 16,1 | AB27: Luis Cuore | AC27: https://www.instagram.com/luiscuore?igsh=MXh2eXd2eWYxMHg3eg== | AD27: 20,1 | AP27: amni | AQ27: 03,2
B28: marc | C28: https://www.instagram.com/marcvivs?igsh=MWRjaWhzZmd5ZmlrdA== | D28: 1,01 | E28: 02,1 | N28: Luis cuore | O28: https://www.instagram.com/luiscuore?igsh=MXh2eXd2eWYxMHg3eg== | P28: 04,1 | Q28: 05,1 | R28: 08,1 | S28: 13,1 | T28: 16,1 | AB28: jeff | AC28: https://www.instagram.com/jeffofor?igsh=MWlyMTJod2JpdGtsNA== | AD28: 22,1 | AE28: 26,1 | AF28: 01,2 | AG28: 03,2 | AH28: 09,2 | AP28: digital prime | AQ28: 05,2
B29: pedro | C29: https://www.instagram.com/pedrohmontero?igsh=bjc4emp5cmw4Y3l6 | D29: 1,01 | E29: 02,1 | K29: YES | N29: milky | O29: https://www.instagram.com/mikydata?igsh=MThvc3licnJ2ZXh6ZA== | P29: 04,1 | Q29: 05,1 | R29: 13,1 | AP29: jeff | AQ29: 09,2
B30: dani | C30: https://www.instagram.com/dani.ssuarez?igsh=MTE1cGZzMHh5Z2Fsbg== | D30: 1,01 | E30: 02,1 | K30: YES | N30: Javier | O30: https://www.instagram.com/javier.botia?igsh=emc5NHVjemwwOG5z | P30: 05,1 | Q30: 05,1 | AB30: Adri | AC30: https://www.instagram.com/adriigonzalezg?igsh=eDl0ejRvazNxN2R4 | AD30: 23,1 | AE30: 26,1 | AF30: 28,1 | AG30: 30,1 | AH30: 01,2 | AI30: 03,2 | AJ30: 05,2 | AK30: 06,2
B31: hyrox trainer | C31: https://www.instagram.com/jmpfunxional?igsh=bjB5aWpiNnM0em8z | D31: 1,01 | E31: 02,1 | K31: YES | N31: Raul | O31: https://www.instagram.com/raul_sansegundo?igsh=c2I5dncxNXZwZGVx | P31: 04,1 | AB31: Adrian | AC31: https://www.instagram.com/arquelladas13?igsh=MTd4cm9qY284ZzhvOA== | AD31: 23,1 | AE31: 26,1
B32: javi | C32: https://www.instagram.com/javidontri?igsh=N3BlZ2ZlNzd3b3Zp | D32: 1,01 | E32: 02,1 | F32: nq | K32: YES | N32: eclipse y sirena | O32: https://www.instagram.com/eclipseysirena?igsh=Mmo5c29zN2dneDhv | P32: 06,1 | Q32: 08,1 | R32: 09,1 | AB32: digital prime | AC32: https://www.instagram.com/digitalprimesolutions?igsh=MXJ1eW1iN20xN2toZw== | AD32: 27,1 | AE32: fup vie | AF32: 30,1 | AG32: 01,2 | AH32: 03,2
B33: aguilera | C33: https://www.instagram.com/f.aguileradiaz?igsh=dzVmcmc4c2JtdGV6 | D33: 1,01 | E33: 02,1 | F33: nq | K33: YES | N33: Multiaventura | O33: https://www.instagram.com/charm_multiaventura?igsh=NHJ0ZGpjM2RoejU= | P33: 06,1 | Q33: 09,1 | R33: nq | AB33: Alex Gamarra | AC33: https://www.instagram.com/gamarra.psd?igsh=MXc4MXppMHd0NGxzZw== | AD33: 27,1 | AE33: 28,1 | AF33: ni
B34: joan | C34: https://www.instagram.com/jooaan_0?igsh=MXV3MXJ0djMwa2oybg== | D34: 1,01 | E34: 02,1 | F34: nq | K34: YES | N34: alex | O34: https://www.instagram.com/aleexx69ssj?igsh=ZzNzOHk0OXcwajNt | P34: 07,1 | Q34: obj | R34: 13,1 | S34: 16,1 | T34: 20,1 | U34: nq | AB34: Yohanna | AC34: https://www.instagram.com/yohanasancheze?igsh=enVuZm15aTBraWV6 | AD34: 27,1 | AE34: fup vie | AF34: 30,1 | AG34: 01,2 | AH34: 03,2 | AI34: 06,2 | AJ34: fup abr
B35: Arnau | C35: https://www.instagram.com/arnauturner?igsh=MXZveDVsa3RteGlvag== | D35: 1,01 | E35: 02,1 | K35: YES | N35: Andrea | O35: https://www.instagram.com/soyandreacrea?igsh=aDh2OTk3dHBjZTV3 | P35: 07,1 | Q35: 08,1 | R35: 10,1 | AB35: amni | AC35: https://www.instagram.com/aminpr_?igsh=MXF0azBwYW4zeGd4eg== | AD35: 02,2 | AE35: 03,2
B36: Israel | C36: https://www.instagram.com/israelrecio_06?igsh=MWk2bmE2cjNneXc5bg== | D36: 02,1 | E36: 03,1 | K36: YES | N36: Alvaro | O36: https://www.instagram.com/9.alvaro_ms?igsh=MTRxbnpkanV0MWU2YQ== | P36: 06,1 | Q36: 08,1
B37: Alejandro | C37: https://www.instagram.com/soy.alejandro.bernabe?igsh=MWtoem9kbmUwOHJ2MQ== | D37: 02,1 | E37: 03,1 | K37: YES | N37: Abel | O37: https://www.instagram.com/abel_casado?igsh=ZzMydHUwOXU5bHZ4 | P37: 09,1 | Q37: nq
B38: marcelo | C38: https://www.instagram.com/marceloperezsanders?igsh=aDQ1dWEwY3Btbjd1 | D38: 02,1 | E38: 03,1 | K38: YES | N38: Cesar | O38: https://www.instagram.com/22cesargomez22?igsh=MWI3NWg1Ymx0NXAxaA== | P38: 08,1 | Q38: 13,1 | R38: 16,1 | S38: 20,1 | T38: 21,1 | U38: 26,1
B39: fermin | C39: https://www.instagram.com/fermincreativo?igsh=MTluN2F6N3BvZTR1dQ== | D39: 02,1 | E39: 03,1 | F39: obj | K39: YES | N39: Nieel | O39: https://www.instagram.com/nieel?igsh=aDZ0cDlveG1zdTF2 | P39: 09,1
B40: andres | C40: https://www.instagram.com/andres.milea?igsh=MWUwNzg2Ynl2enVrOA== | D40: 02,1 | E40: 03,1 | F40: nq | K40: YES | N40: Alejandro | O40: https://www.instagram.com/alemnozz?igsh=amFxbHB3dDR0MW4w | P40: 11,1 | Q40: 13,1 | R40: 16,1 | S40: 20,1
B41: tumarca asegurada | C41: https://www.instagram.com/tumarcaasegurada?igsh=dG82YTlvOGFlZ2Zx | D41: 02,1 | E41: 03,1 | K41: YES | N41: Pedro | O41: https://www.instagram.com/oioiesa?igsh=MXd4Z3JzdjRlcHJ5Zw== | P41: 11,1 | Q41: 13,1 | R41: 16,1 | S41: 20,1 | T41: 21,1 | U41: 26,1
B42: montse | C42: https://www.instagram.com/montse_iscla?igsh=NGJpZGpzc2gxNmho | D42: 02,1 | E42: 03,1 | F42: nq | K42: YES | N42: felix | O42: https://www.instagram.com/felixpichardo.ff?igsh=MWNlcGdzcng3Z3luNw== | P42: 10,1
B43: jose luis | C43: https://www.instagram.com/joseluis.chuchullo?igsh=MWltbmo3OHh1YWllaA== | D43: 02,1 | E43: 03,1 | K43: YES | N43: ismael babinou | O43: https://www.instagram.com/ismaelbabinoufit?igsh=NjcxMXZncjRqZ3k5 | P43: 10,1
...

Sheet Feb
B2: © Imperium Agency - All rights reserved. Do not share, copy, reproduce or sell any part of this document unless you have written permission from Imperium Labs LTD. All infringements will be prosecuted. If you are the personal owner of the Imperium Labs LTD End User License then you may use it for your own use but not for any other purpose.
C4: Stage | D4: Prospects | F4: Overall | G4: Conversion % | I4: Stage | J4: Conversion %
C5: (A) | D5: =COUNTIF(B13:B1000, "<>") -> 409 | F5: MSR | G5: =D6/D5 -> 0.026894866 | I5: A > MS | J5: =D6/D5 -> 0.026894866 | O5: Requests | P5: Accepted | Q5: CAR%
C6: (MS) | D6: =COUNTIF(K13:K1000, "YES") -> 11 | F6: PRR | G6: =D7/D5 -> 0.13447433 | I6: MS > B | J6: =D7/D6 -> 5 | Q6: =P6/O6 -> #DIV/0!
C7: (B) | D7: =COUNTIF(N13:N1000, "<>") -> 55 | F7: CSR | G7: =D8/D5 -> 0.039119804 | I7: B > C | J7: =D8/D7 -> 0.29090909
C8: (C) | D8: =COUNTIF(AC13:AC1000, "<>") -> 16 | F8: ABR | G8: =D9/D5 -> 0.024449878 | I8: C > D | J8: =D9/D8 -> 0.625
C9: (D) | D9: =COUNTIF(AQ13:AQ1000, "<>") -> 10
B11: To make a copy go file > make a copy
B12: Name (Initiate) (A) | C12: Profile Link | D12: Date Initiated | E12: 1A | F12: Notes | K12: Media Seen (MS) | N12: Name (Engaged) (B) | O12: Profile Link | P12: Date Engaged | Q12: 1B | R12: 2B | S12: 3B | T12: 4B | V12: 5B | W12: 6B | X12: 7B | Y12: 8B | Z12: Notes | AC12: Name (C) | AD12: Profile Link | AE12: Date (C) | AF12: 1C | AG12: 2C | AH12: 3C | AI12: 4C | AJ12: 5C | AK12: 6C | AL12: 7C | AM12: 8B | AN12: Notes | AQ12: Name (D) | AR12: Date (D) | AS12: Notes
B13: jorge | C13: https://www.instagram.com/jorgee.mc5?igsh=MWY2N2syNXBpaWFvOQ== | D13: 02,2 | E13: 04,2 | K13: YES | N13: Mario | O13: https://www.instagram.com/ruralmetal20?igsh=cXU5b2Rwc3l6b2F2 | P13: 03,2 | Q13: 04,2 | R13: 06,2 | S13: 07,2 | T13: 09,2 | AC13: Marcela | AD13: https://www.instagram.com/artbychela?igsh=MXZjYTBjZDA0N2p2ZA== | AE13: 10,2 | AQ13: fernando | AR13: 10,2
B14: silvia | C14: https://www.instagram.com/silviagallardogabella?igsh=aXFwdXdjemh0ZHJh | D14: 02,2 | E14: 04,2 | F14: ni | K14: YES | N14: Fernando | O14: https://www.instagram.com/fernando_acevedo_guerrero?igsh=dzc0ZDVsdzYzZW00 | P14: 03,2 | Q14: 04,2 | R14: 06,2 | S14: 07,2 | T14: 09,2 | AC14: andres mates | AD14: https://www.instagram.com/matesconandres?igsh=MXc5c2gyNTMyanR2bw== | AE14: 10,2 | AQ14: mario | AR14: 10,2
B15: belen | C15: https://www.instagram.com/belen_3324?igsh=cGFnNXZxN3plNDlz | D15: 02,2 | E15: 04,2 | N15: sergi | O15: https://www.instagram.com/_sergii.c_?igsh=ODV2NTlreTI5NXRt | P15: 03,2 | Q15: 04,2 | R15: 06,2 | S15: 07,2 | T15: 09,2 | V15: fup abril | AC15: mario | AD15: https://www.instagram.com/ruralmetal20?igsh=cXU5b2Rwc3l6b2F2 | AE15: 10,2 | AQ15: marcela | AR15: 11,2
B16: emilio | C16: https://www.instagram.com/_emiliogarcia_?igsh=MWtybnhxaGoyaHZpNQ== | D16: 02,2 | E16: 04,2 | K16: YES | N16: jorge | O16: https://www.instagram.com/jorgesuelves/ | P16: 05,2 | R16: 06,2 | S16: 07,2 | T16: obj | V16: 12,2 | AC16: Fernando | AD16: https://www.instagram.com/fernando_acevedo_guerrero?igsh=dzc0ZDVsdzYzZW00 | AE16: 10,2 | AQ16: Andrés | AR16: 11,2
B17: mario | C17: https://www.instagram.com/ruralmetal20?igsh=cXU5b2Rwc3l6b2F2 | D17: 02,2 | E17: 04,2 | K17: YES | N17: Cantabella | O17: https://www.instagram.com/cantabellajm?igsh=N3p1OWk4N2Frc2Nt | P17: 05,2 | Q17: 10,2 | R17: 11,2 | S17: 15,2 | T17: 18,2 | U17: 20,2 | V17: 23,2 | AC17: ivan | AD17: https://www.instagram.com/ivanschztrainer?igsh=MTd1c2lyc2M4dzFpMQ== | AE17: 11,2 | AQ17: ivan | AR17: 11,2
B18: fran | C18: https://www.instagram.com/francarne_oficial?igsh=MWxsMGdkNjg5eTZtMQ== | D18: 02,2 | E18: 04,2 | K18: YES | N18: Lorena | O18: https://www.instagram.com/lorena_llorente_copywriter?igsh=aWtocWVlOXd5djgx | P18: 08,2 | R18: nur | AC18: moad | AD18: https://www.instagram.com/moaadd.gh?igsh=bDZueGtlZzNxenY5 | AE18: 13,2 | AF18: 15,2 | AG18: fup may | AQ18: Digital prime | AR18: 20,2
B19: driss | C19: https://www.instagram.com/_driss_48?igsh=cjN2cDdxaHJweXF3 | D19: 02,2 | E19: 04,2 | K19: YES | N19: Andres mates | O19: https://www.instagram.com/matesconandres?igsh=MXc5c2gyNTMyanR2bw== | P19: 08,2 | Q19: 09,2 | AC19: shiva | AD19: https://www.instagram.com/shiva.project.world?igsh=MTNieGpsZm1sd3ZvMQ== | AE19: 21,2 | AQ19: shiva | AR19: 20,2
B20: jorge | C20: https://www.instagram.com/jorgediaz662024?igsh=MWVqb3h4Zm54enBjMA== | D20: 02,2 | E20: 04,2 | N20: mateo | O20: https://www.instagram.com/_mateo.mdz6?igsh=MXFnMW44am1xNTRpeQ== | P20: 09,2 | Q20: 10,2 | R20: 11,2 | S20: nq | AC20: Carlos | AD20: https://www.instagram.com/dr.carloscasado?igsh=amtiemZlZzF1MWs4 | AE20: 23,2 | AF20: fup marzo | AQ20: Mauro | AR20: 28,2
B21: marcela | C21: https://www.instagram.com/artbychela?igsh=MXZjYTBjZDA0N2p2ZA== | D21: 02,2 | E21: 04,2 | F21: obj | N21: martin | O21: https://www.instagram.com/maartiints?igsh=MXZhamptNGY0bXozMw== | P21: 09,2 | Q21: 10,2 | R21: 11,2 | S21: 12,2 | AC21: Andres | AD21: https://www.instagram.com/andres_asoya?igsh=MTVzYjdlZ2hhaXFidA== | AE21: 25,2 | AQ21: Vicent | AR21: 28,2
B22: monica | C22: https://www.instagram.com/monica.chicpink?igsh=MXRocXVqNDR3ZDJmbA== | D22: 02,2 | E22: 04,2 | N22: Dani | O22: https://www.instagram.com/dani.martinmoreno?igsh=MTV3Y3Zha2Q1bmp1bg== | P22: 09,2 | Q22: ni | AC22: Raquel | AD22: https://www.instagram.com/raquel_sumarroca?igsh=MTVrajljZjJoeGJ6Yw== | AE22: 25,2 | AQ22: neurografica | AR22: 3,3
B23: manuel | C23: https://www.instagram.com/manuel_martin_capital?igsh=M214cTk2MWl2MDhp | D23: 02,2 | E23: 04,2 | K23: YES | N23: marcela | O23: https://www.instagram.com/artbychela?igsh=MXZjYTBjZDA0N2p2ZA== | P23: 09,2 | AC23: Daniel | AD23: https://www.instagram.com/dp019_?igsh=Y3U2MGV6bjg4OTFk | AE23: 27,2 | AF23: 28,2 | AG23: 2,3 | AH23: 3,3 | AI23: 12,3
B24: jorge | C24: https://www.instagram.com/jorgesuelves?igsh=MXZkYXRkMWxhejgw | D24: 02,2 | E24: 04,2 | N24: sr dog | O24: https://www.instagram.com/src_dog?igsh=MW5jeWc3YWNtdHRmbA== | P24: 10,2 | Q24: 11,2 | R24: 15,2 | S24: 18,2 | T24: 20,1 | AC24: Neurografica | AD24: https://www.instagram.com/neuro.grafica.es?igsh=amUxb2dyaW5jOXg1 | AE24: 28,2 | AF24: 2,3
B25: fernando | C25: https://www.instagram.com/fernando_acevedo_guerrero?igsh=dzc0ZDVsdzYzZW00 | D25: 02,2 | E25: 04,2 | K25: YES | N25: ivan | O25: https://www.instagram.com/ivanschztrainer?igsh=MTd1c2lyc2M4dzFpMQ== | P25: 11,2 | Q25: test | AC25: Pablo josé | AD25: https://www.instagram.com/bypablogomez?igsh=Z2ljZjVrc3V4ZzBk | AE25: 27,2 | AF25: 2,3 | AG25: 3,3 | AI25: 12,3
B26: valen | C26: https://www.instagram.com/valen_tuset?igsh=MWdtaXU4aHVqcTB5Zw== | D26: 03,2 | E26: 04,2 | N26: jose | O26: https://www.instagram.com/joseruizmartinez?igsh=c3R3d2FvbHh3aGR0 | P26: 11,2 | Q26: test | R26: 12,2 | S26: 15,2 | T26: 18,2 | U26: 20,2 | V26: 23,2 | W26: 25,2 | AC26: Mauro | AD26: https://www.instagram.com/soymaurhojimenez?igsh=MXE3dHFjOGlhYmdleg== | AE26: 28,2
B27: sergi | C27: https://www.instagram.com/_sergii.c_?igsh=ODV2NTlreTI5NXRt | D27: 03,2 | E27: 04,2 | K27: YES | N27: izumi | O27: https://www.instagram.com/izumishoji_?igsh=MWlnMG5ibGVhMm9rYQ== | P27: 11,2 | Q27: test | R27: fup may | AC27: Vicent | AD27: https://www.instagram.com/vicent__episodios_altos?igsh=MWhmdGxsdWwydmN2dQ== | AE27: 28,2
B28: francisco | C28: https://www.instagram.com/franciscojaviercalerovelasc?igsh=eWY4bnFlMW5jcnph | D28: 03,2 | E28: 04,2 | N28: moadd | O28: https://www.instagram.com/moaadd.gh?igsh=bDZueGtlZzNxenY5 | P28: 12,2 | Q28: 13,2 | AC28: automatiza pro | AD28: https://www.instagram.com/automatiza__pro?igsh=enFrZmdzcWxrZ3Ru | AE28: 26,2 | AF28: 12,3
B29: lucas | C29: https://www.instagram.com/lucasallende?igsh=MTJnaXQzaXozdmVqcg== | D29: 03,2 | E29: 04,2 | K29: YES | N29: javi | O29: https://www.instagram.com/javi.pardos?igsh=N3BlYnoyZTQ1enRj | P29: 12,2 | Q29: 13,2 | R29: test | S29: 15,2 | T29: 18,2 | U29: 20,2 | V29: 23,2 | W29: 25,2
B30: steven | C30: https://www.instagram.com/stevenrea6?igsh=c3Y1cWZqemQwNzE4 | D30: 03,2 | E30: 04,2 | K30: YES | N30: david casasola | O30: https://www.instagram.com/davidcasasola_mentor?igsh=ZGV2ZGlqbXdpeGcx | P30: 12,2 | Q30: 13,2 | R30: test | S30: 15,2 | T30: 18,2 | U30: 20,2 | V30: 23,2 | W30: 25,2 | X30: 27,2 | Y30: 2,3
B31: carlos | C31: https://www.instagram.com/carlos884388?igsh=MWVnaWtpd2JpYTI4aQ== | D31: 03,2 | E31: 04,2 | N31: adrian | O31: https://www.instagram.com/soyadriannieto?igsh=N3p0MXlmY3oyazJp | P31: 12,2 | Q31: 13,2 | R31: test | S31: 15,2 | T31: Obj | U31: 20,2 | V31: 23,2 | W31: fup abril
B32: marc | C32: https://www.instagram.com/marc.ferrerr_?igsh=OHFoem5hYjc3YXF4 | D32: 03,2 | E32: 04,2 | F32: nq | N32: Alejandro | O32: https://www.instagram.com/tobar__tc?igsh=bnRycnNyZjVqMGRt | P32: 15,2 | Q32: test | S32: 15,2 | T32: 18,2 | U32: 20,2
B33: zaira | C33: https://www.instagram.com/zairamartineslopez?igsh=MWJwcDg2aXk0ZXdhYg== | D33: 04,2 | E33: 06,2 | N33: Lorena | O33: https://www.instagram.com/trincheralibre?igsh=MW85ZGR3dzRwM3Vy | P33: 13,2 | Q33: test | R33: 15,2 | S33: 15,2 | T33: 18,2 | U33: 20,2 | V33: 23,2 | W33: 25,2 | X33: 27,2 | Y33: 2,3
B34: cantabella | C34: https://www.instagram.com/cantabellajm?igsh=N3p1OWk4N2Frc2Nt | D34: 04,2 | E34: 06,2 | N34: Aitor | O34: https://www.instagram.com/aitoor.fr?igsh=MmwxMGM0amZtYm1o | P34: 15,2 | Q34: 16,2 | S34: 15,2 | T34: 18,2 | U34: Nq
B35: Dario | C35: https://www.instagram.com/darioosr__011?igsh=MzRlNW83MWl6Ym92 | D35: 04,2 | E35: 06,2 | F35: ni | N35: irina | O35: https://www.instagram.com/irina_theartofhealing?igsh=dHdyeXo5OWpmeHJv | P35: 15,2 | Q35: 16,2 | R35: test | S35: 15,2 | T35: 18,2 | U35: 20,2 | V35: 23,2 | W35: 25,2 | X35: 27,2 | Y35: 5,3
B36: elyas | C36: https://www.instagram.com/elyasmkt?igsh=eGFjeGVzc2hzc2gx | D36: 04,2 | E36: 06,2 | N36: bruno | O36: https://www.instagram.com/_brunooalc?igsh=MTRwdDhjb3R5cm1zYw== | P36: 17,2 | Q36: 18,2 | R36: Ni
B37: Fanny | C37: https://www.instagram.com/fannyamaryser?igsh=MWNudTVsbnpjZWs1cw== | D37: 04,2 | E37: 06,2 | N37: Rocio | O37: https://www.instagram.com/rocioorozco.english?igsh=MWZzYnR2ZWx2NzNvcw== | P37: 18,2 | Q37: 19,2 | R37: Fup may
B38: Ari | C38: https://www.instagram.com/arianna_manicardi?igsh=cmh2cDV4MzBvbzU0 | D38: 04,2 | E38: 06,2 | N38: Raquel | O38: https://www.instagram.com/raquel_sumarroca?igsh=MTVrajljZjJoeGJ6Yw== | P38: 18,2 | Q38: 19,2 | R38: 20,2 | S38: 23,2
B39: growix | C39: https://www.instagram.com/d.m_growixagency?igsh=NGtzcXNxdGUxdTBl | D39: 04,2 | E39: 06,2 | N39: Adrian | O39: https://www.instagram.com/maaarees?igsh=MXJhY2tsYnBhaDJueg== | P39: 19,2 | Q39: 20,2 | R39: 23,2 | S39: 25,2
B40: Emilio | C40: https://www.instagram.com/emiliolr92?igsh=MXd0dmF1bHBjaWtoZw== | D40: 04,2 | E40: 06,2 | N40: Carlos | O40: https://www.instagram.com/dr.carloscasado?igsh=amtiemZlZzF1MWs4 | P40: 20,2
B41: Pelao | C41: https://www.instagram.com/pelao_shooting_brake?igsh=MXI2bGxucnIwNTc3Mg== | D41: 04,2 | E41: 06,2 | N41: sastre | O41: https://www.instagram.com/_saastre?igsh=OGs3eHdrNXN5M3Vt | P41: 20,2 | Q41: 21,2 | R41: fup may
B42: Ruben | C42: https://www.instagram.com/casualidad_r?igsh=NmJrMDRxOXBhMjZq | D42: 04,2 | E42: 06,2 | N42: retrato del aoma | O42: https://www.instagram.com/retratodealmagemela?igsh=MTE4cHkwZmQ4aWs4dA== | P42: 20,2 | Q42: 21,2 | R42: 23,2 | S42: 25,2 | T42: obj | U42: 27,2 | V42: up martes | W42: 3,3 | X42: 5,3 | Y42: 9,3 | Z42: 10,3
B43: Edgar | C43: https://www.instagram.com/edgar.finance?igsh=MWU2MGxkYm42d3Q3dQ== | D43: 04,2 | E43: 06,2 | N43: pablo José | O43: https://www.instagram.com/bypablogomez?igsh=Z2ljZjVrc3V4ZzBk | P43: 20,2 | Q43: 21,2 | R43: 23,2 | S43: 25,2 | T43: 27,2
...

Sheet Mar
B2: © Imperium Agency - All rights reserved. Do not share, copy, reproduce or sell any part of this document unless you have written permission from Imperium Labs LTD. All infringements will be prosecuted. If you are the personal owner of the Imperium Labs LTD End User License then you may use it for your own use but not for any other purpose.
C4: Stage | D4: Prospects | F4: Overall | G4: Conversion % | I4: Stage | J4: Conversion %
C5: (A) | D5: =COUNTIF(B13:B1000, "<>") -> 686 | F5: MSR | G5: =D6/D5 -> 0 | I5: A > MS | J5: =D6/D5 -> 0 | O5: Requests | P5: Accepted | Q5: CAR%
C6: (MS) | D6: =COUNTIF(K13:K1000, "YES") -> 0 | F6: PRR | G6: =D7/D5 -> 0.12099125 | I6: MS > B | J6: =D7/D6 -> #DIV/0! | Q6: =P6/O6 -> #DIV/0!
C7: (B) | D7: =COUNTIF(N13:N1000, "<>") -> 83 | F7: CSR | G7: =D8/D5 -> 0.051020408 | I7: B > C | J7: =D8/D7 -> 0.42168675
C8: (C) | D8: =COUNTIF(AB13:AB1000, "<>") -> 35 | F8: ABR | G8: =D9/D5 -> 0.034985423 | I8: C > D | J8: =D9/D8 -> 0.68571429
C9: (D) | D9: =COUNTIF(AP13:AP1000, "<>") -> 24
B11: To make a copy go file > make a copy
B12: Name (Initiate) (A) | C12: Profile Link | D12: Date Initiated | E12: 1A | F12: Notes | K12: Media Seen (MS) | N12: Name (Engaged) (B) | O12: Profile Link | P12: Date Engaged | Q12: 1B | R12: 2B | S12: 3B | T12: 4B | U12: 5B | V12: 6B | W12: 7B | X12: 8B | Y12: Notes | AB12: Name (C) | AC12: Profile Link | AD12: Date (C) | AE12: 1C | AF12: 2C | AG12: 3C | AH12: 4C | AI12: 5C | AJ12: 6C | AK12: 7C | AL12: 8B | AM12: Notes | AP12: Name (D) | AQ12: Date (D) | AR12: Notes
B13: money and kids | C13: https://www.instagram.com/money.and.kids?igsh=djlnN3g0dzUxMjBn | D13: 1,3 | E13: 3,3 | N13: Ocb | O13: https://www.instagram.com/ocb1.000?igsh=aWFyYXJxc2Rwbmxv | P13: 4,3 | Q13: 6,3 | R13: 9,3 | AB13: kevin | AC13: https://www.instagram.com/kevinschattmann_?igsh=c2h1cDF2Nng3OGV | AD13: 6,3 | AP13: kevin | AQ13: 6,3
B14: sergiolest | C14: https://www.instagram.com/seergiolest?igsh=eWV0MmN1d2xxb2g3 | D14: 1,3 | E14: 3,3 | N14: jara | O14: https://www.instagram.com/jara_hardwick?igsh=MTBhZjMwYWJjazJycw== | P14: 4,5 | Q14: 9,3 | AB14: pablo | AC14: https://www.instagram.com/pabloalv.s?igsh=MTF3bzZmY3d2cDBnYw== | AD14: 6,3 | AP14: pablo | AQ14: 6,3
B15: luisferr | C15: https://www.instagram.com/luisferrr2579905?igsh=MTF5d2lveWticHk0NQ== | D15: 1,3 | E15: 3,3 | N15: adrian | O15: https://www.instagram.com/_adriangarciaz?igsh=eDRtcGw4eHVxdjB5 | P15: nq | AB15: guille | AC15: https://www.instagram.com/guille_drums?igsh=MWZlOTVpOTNyOGE1Zw== | AD15: 6,3 | AP15: guille | AQ15: 6,3
B16: linda | C16: https://www.instagram.com/linda_godoysamudio?igsh=MWxpcTlpeTA2MTIwcw== | D16: 1,3 | E16: 3,3 | N16: Saul | O16: https://www.instagram.com/saulvalor?igsh=MWdsZGd3M21rbTN4bQ== | P16: 5,3 | Q16: ni | AB16: ines | AC16: https://www.instagram.com/inescadenag?igsh=NGxzNGV6M3Z2Nmdx | AD16: 9,3 | AP16: ines | AQ16: 9,3
B17: ultracentro | C17: https://www.instagram.com/ultracentr0?igsh=b3Q4dHRteGQ3NWpl | D17: 1,3 | E17: 3,3 | F17: Nq | N17: agharta yoga | O17: https://www.instagram.com/agharta.yoga?igsh=d3dzZTk1d2hwcG5r | P17: 4,3 | Q17: 5,3 | R17: 12,3 | S17: 14,3 | AB17: jara | AC17: https://www.instagram.com/jara_hardwick?igsh=MTBhZjMwYWJjazJycw== | AD17: 9,3 | AP17: jara | AQ17: 9,3
B18: mentalidad dinero | C18: https://www.instagram.com/mentalidadinero?igsh=MWhuNzhpZ2lhdWhqMw== | D18: 1,3 | E18: 3,3 | F18: Ni | N18: Pablo | O18: https://www.instagram.com/pabloalv.s?igsh=MTF3bzZmY3d2cDBnYw== | P18: 4,3 | Q18: 5,3 | AB18: alvaro | AC18: https://www.instagram.com/pilatesone2one?igsh=MTExdHN4a2h0N3YwYQ== | AD18: 10,3 | AE18: 12,3 | AP18: daniel | AQ18: 11,3
B19: privatesecurity | C19: https://www.instagram.com/privatesecurityprojects?igsh=d3hqcmwxYzF2bXh0 | D19: 1,3 | E19: 3,3 | N19: aimo | O19: https://www.instagram.com/aimo.247?igsh=MXBwYmhvZnZqNjVsbA== | P19: 5,3 | Q19: 6,3 | R19: 9,3 | S19: 10,3 | T19: Fup lunes | U19: 17,3 | AB19: enrique | AC19: https://www.instagram.com/henrysinmas?igsh=MWh3b2NxaWV4M2VsaQ== | AD19: 10,3 | AE19: 11,3 | AF19: 12,3 | AG19: 17,3 | AP19: sergi | AQ19: 13,3
B20: raul | C20: https://www.instagram.com/soyraulmunoz?igsh=NngyeTFpNWR6dDNn | D20: 1,3 | E20: 3,3 | N20: kevin | O20: https://www.instagram.com/kevinschattmann_?igsh=c2h1cDF2Nng3OGV | P20: 5,3 | Q20: 6,3 | R20: obj | AB20: sylvia | AC20: https://www.instagram.com/sylviamastay.tarotyletras?igsh=N2p2b3RpOTh3N2pq | AD20: 11,3 | AE20: 12,3 | AP20: ian pacheco | AQ20: 15,3
B21: ocb | C21: https://www.instagram.com/ocb1.000?igsh=aWFyYXJxc2Rwbmxv | D21: 3,3 | N21: jordi | O21: https://www.instagram.com/hipnosisjordimartinez?igsh=YWRodzVjODBtNGYx | P21: 5,3 | Q21: 6,3 | R21: 12,3 | S21: 14,3 | AB21: daniel | AC21: https://www.instagram.com/inglesconcalle?igsh=MXg5Znp4OWZncmZsZQ== | AD21: 9,3 | AP21: alejandro | AQ21: 16,3
B22: mariona | C22: https://www.instagram.com/marionacer_cast?igsh=bmZxcTR6bXdtejcx | D22: 3,3 | E22: 4,3 | N22: alvaro | O22: https://www.instagram.com/pilatesone2one?igsh=MTExdHN4a2h0N3YwYQ== | P22: 5,3 | Q22: 6,3 | AP22: virginia | AQ22: 18,3
B23: 11 arc | C23: https://www.instagram.com/_11.a.r.c_?igsh=MWhldTJzOXQ4MGswOA== | D23: 3,3 | E23: 4,3 | F23: nq | N23: enrique | O23: https://www.instagram.com/henrysinmas?igsh=MWh3b2NxaWV4M2VsaQ== | P23: 5,3 | Q23: 6,3 | R23: 10,3 | AB23: sergi | AC23: https://www.instagram.com/sergicandel?igsh=c3hxODlqOTN0NHRt | AD23: 13,3 | AP23: javier | AQ23: 18,3
B24: esperanza | C24: https://www.instagram.com/esperanzarigogarcias?igsh=MTQ3NncwdXEwcmNpOQ== | D24: 3,3 | E24: 4,3 | N24: sylvia | O24: https://www.instagram.com/sylviamastay.tarotyletras?igsh=N2p2b3RpOTh3N2pq | P24: 6,3 | AB24: biomecanica del pianista | AC24: https://www.instagram.com/biomecanicadelpianista?igsh=MXV6NnB6dXJkZnlvag== | AD24: 11,3 | AE24: 17,3 | AF24: 19,3 | AP24: llana | AQ24: 19,3
B25: adrian | C25: https://www.instagram.com/_adriangarciaz?igsh=eDRtcGw4eHVxdjB5 | D25: 3,3 | E25: 4,3 | F25: nq | N25: guille | O25: https://www.instagram.com/guille_drums?igsh=MWZlOTVpOTNyOGE1Zw== | P25: 6,3 | AB25: alejandro | AC25: https://www.instagram.com/alejoaponteu?igsh=MWxwbGU5MWw2dW4yZw== | AD25: 16,3 | AP25: isma | AQ25: 19,3
B26: ortiz | C26: https://www.instagram.com/ortiz___cx?igsh=YzBubDR4bjVtempt | D26: 3,3 | E26: 4,3 | N26: sylvia | O26: https://www.instagram.com/sylviamastay.tarotyletras?igsh=N2p2b3RpOTh3N2pq | P26: 6,3 | Q26: 7,3 | R26: 10,3 | AB26: virginia | AC26: https://www.instagram.com/virginia.gonzalez1?igsh=MTg0OGltcmV1Ymsxbg== | AD26: 18,3 | AP26: jordi | AQ26: 19,3
B27: ignacio | C27: https://www.instagram.com/ignacioalonsoimn?igsh=NHBwZ3BvOHN5b2Zv | D27: 3,3 | E27: 4,3 | N27: ines | O27: https://www.instagram.com/inescadenag?igsh=NGxzNGV6M3Z2Nmdx | P27: 6,3 | Q27: no vsl | AB27: isma | AC27: https://www.instagram.com/ismacardd?igsh=MWZxdTE1MTkwdG5yOA== | AD27: 18,3 | AP27: izan | AQ27: 23,3
B28: david | C28: https://www.instagram.com/david_gp2020?igsh=MTVuMDVsajJ1ZzFiYw== | D28: 3,3 | E28: 4,3 | N28: adrian | O28: https://www.instagram.com/adrianbenitez113?igsh=NXoxbWtkNTlwaDJ0 | P28: 6,3 | AB28: llana | AC28: https://www.instagram.com/srlallana?igsh=NzVmMDdjcm9hazRh | AD28: 18,3 | AP28: Cristian martinez | AQ28: 24,3
B29: atezz | C29: https://www.instagram.com/atezz_bts_stray?igsh=aGdtbXl0aHBnMDJu | D29: 3,3 | E29: 4,3 | N29: ivan | O29: https://www.instagram.com/jmnzrun?igsh=ajQ5MmM2NTAyMGNi | P29: 7,3 | Q29: 8,3 | R29: nq | AB29: Carlos | AC29: https://www.instagram.com/priv.fernandez_bote?igsh=MW0yb2Z1MHg2YTI2Yg== | AD29: 19,3 | AE29: nq | AP29: Julieta | AQ29: 24,3
B30: lucas | C30: https://www.instagram.com/lucas.streetlifting?igsh=Y3dyanVlMms3azZ1 | D30: 3,3 | E30: 4,3 | F30: nq | N30: enojarse | O30: https://www.instagram.com/elartedenoenojarse?igsh=bWszMW45Ynp1eTJu | P30: 8,3 | Q30: 10,3 | R30: 12,3 | S30: 14,3 | T30: 17,3 | AB30: javier | AC30: https://www.instagram.com/javierrodriguezblasco?igsh=MXVsZWlqOW0xa2V2eQ== | AD30: 19,3 | AP30: grecia | AQ30: 26,3
B31: paulo | C31: https://www.instagram.com/paulo_torres12?igsh=MTNpNnF0ZHUyOWYwZg== | D31: 3,3 | E31: 4,3 | N31: pietro | O31: https://www.instagram.com/pietro_scianna011?igsh=b2RqZXpueW9tMHBh | P31: 9,3 | Q31: 10,3 | AB31: izan | AC31: https://www.instagram.com/izan_frodo?igsh=MTl5em55Zno3MTRhNw== | AD31: 18,3 | AE31: 19,3 | AF31: 23,3 | AP31: paulo | AQ31: 30,3
B32: christian | C32: https://www.instagram.com/christiandanielvalientegimenez?igsh=MXkyZnEzOGEybDdvZA== | D32: 3,3 | E32: 4,3 | N32: isabella | O32: https://www.instagram.com/bloom__experience?igsh=MTZtcHFwcG85ZHcxOA== | P32: 10,3 | Q32: 11,3 | R32: 12,3 | S32: 14,3 | T32: 17,3 | AB32: jordi | AC32: https://www.instagram.com/ryulife.oficial?igsh=b2E5ZWhoMmZuand1 | AD32: 18,3 | AP32: marioconciencia | AQ32: 30,3
B33: jara | C33: https://www.instagram.com/jara_hardwick?igsh=MTBhZjMwYWJjazJycw== | D33: 3,3 | E33: 4,3 | N33: alex | O33: https://www.instagram.com/pinialex_simracing?igsh=Zm92bmw0Zm1wdnA5 | P33: 11,3 | Q33: 10,3 | R33: 12,3 | S33: 14,3 | AB33: carlos | AC33: https://www.instagram.com/priv.fernandez_bote?igsh=MW0yb2Z1MHg2YTI2Yg== | AD33: 19,3 | AP33: enrique espin | AQ33: 31,3
B34: Kristina | C34: https://www.instagram.com/krysssssy?igsh=MXEwdHlwNWF3ZnRmMw== | D34: 4,3 | N34: biomecanica del pianista | O34: https://www.instagram.com/biomecanicadelpianista?igsh=MXV6NnB6dXJkZnlvag== | P34: 11,3 | Q34: 10,3 | R34: 12,3 | AB34: marioconcie | AC34: https://www.instagram.com/marioconciencia?igsh=MTc5YWMzcjliZGcyOA== | AD34: 21,3 | AE34: fup lunes | AF34: 30,3 | AP34: Rodrigo perez | AQ34: 6,4
B35: Jessica | C35: https://www.instagram.com/hadasdelagaiacosmetica?igsh=MWo1aTFnODJ6aWRjdQ== | D35: 4,3 | F35: ya ha agendado | N35: daniel | O35: https://www.instagram.com/inglesconcalle?igsh=MXg5Znp4OWZncmZsZQ== | P35: 9,3 | Q35: 10,3 | AB35: graciasgrecia | AC35: https://www.instagram.com/graciasgrecia_?igsh=MWFhZ3N3MDA5MzVuNA== | AD35: 23,3 | AP35: luis sanchez | AQ35: 6,4
B36: saul | C36: https://www.instagram.com/saulvalor?igsh=MWdsZGd3M21rbTN4bQ== | D36: 4,3 | N36: rachel | O36: https://www.instagram.com/rachel_peliroja?igsh=MTBkOGFqNGlsNDFmOQ== | P36: 11,3 | Q36: 10,3 | R36: Fup | AB36: c.martinez | AC36: https://www.instagram.com/c.martineznutricion?igsh=MWgzOW9ydTBibDhucQ== | AD36: 24,3 | AP36: santi | AQ36: 7,4
B37: sami | C37: https://www.instagram.com/samiavalos2012?igsh=NmVveTVhcWFrMW1x | D37: 4,3 | E37: 5,3 | N37: gustavo | O37: https://www.instagram.com/gustavotelesca?igsh=MWUyOWFoYnJiaWJmeA== | P37: 10,3 | Q37: 11,3 | R37: 12,3 | S37: 14,3 | AB37: julieta | AC37: https://www.instagram.com/julietaromerolove?igsh=Y2NrZnZzMWw4NmE3 | AD37: 24,3
B38: iris | C38: https://www.instagram.com/irissanchez926?igsh=MTFmMnFqNXBjem95dA== | D38: 4,3 | E38: 5,3 | N38: nacho | O38: https://www.instagram.com/nacho_marquez_guitar?igsh=amF0OHN1cW5idmpi | P38: 10,3 | Q38: 10,3 | AB38: la_muchacha | AC38: https://www.instagram.com/la_muchacha_del_cacao?igsh=eXZtZzZ2NDh0MXE5 | AD38: 24,3
B39: marcos | C39: https://www.instagram.com/marcos_paredes087?igsh=YjhsdDJqMnc5cjdk | D39: 4,3 | E39: 5,3 | N39: cantero | O39: https://www.instagram.com/cantero.noe67?igsh=MXJwcXg2b281azMzOQ== | P39: 11,3 | Q39: 12,3 | R39: 14,3 | S39: 17,3 | AB39: md.gaitan | AC39: https://www.instagram.com/md.gaitan?igsh=ZDY3cTRoeTU0MHkw | AD39: 23,3 | AE39: 26,3 | AF39: 30,3 | AG39: 8,4
B40: edu | C40: https://www.instagram.com/eduardovaldez__?igsh=czdqNHpjZTU1dWw0 | D40: 4,3 | E40: 5,3 | N40: maik | O40: https://www.instagram.com/maikcambet?igsh=eHJvNmZkZXRoZDUz | P40: 11,3 | Q40: 12,3 | R40: 14,3 | S40: Obj | T40: 19,3 | AB40: bencosmik | AC40: https://www.instagram.com/bencosmik.om.universe?igsh=MWVqbTM1ZHFtcnJmcA== | AD40: 26,3 | AE40: 30,3
B41: larissa | C41: https://www.instagram.com/larissamelo74?igsh=MTI2bWF5amNvbXRmZA== | D41: 4,3 | E41: 5,3 | N41: fgp | O41: https://www.instagram.com/fgp_24?igsh=MzJnYm5mOXNvMGJm | P41: 11,3 | Q41: 12,3 | R41: 14,3 | AB41: fer | AC41: https://www.instagram.com/ferfabrifer?igsh=ZXZ1bG4zZWM3ajBx | AD41: 27,3 | AE41: 30,3 | AF41: 8,4
B42: mathias | C42: https://www.instagram.com/math.veronfx?igsh=MW1odncyb2V1NzFtNg== | D42: 4,3 | E42: 5,3 | N42: ivan | O42: https://www.instagram.com/ivann.sanchzz?igsh=bmMxeHN0cGJxYnBo | P42: 11,3 | Q42: 12,3 | R42: 14,3 | S42: 17,3 | T42: Fup 27 | AB42: emi.bernard | AC42: https://www.instagram.com/emi.benard?igsh=Ym1kNzk2N2NmODA= | AD42: 23,3 | AE42: 30,3
B43: tomas | C43: https://www.instagram.com/tomas.puentes.526?igsh=MW1xZTl4N2NsNmd2Zg== | D43: 4,3 | E43: 5,3 | N43: pablo | O43: https://www.instagram.com/finanzasbypablo?igsh=MTltNHcycXJsZzU2eg== | P43: 11,3 | Q43: a2,3 | R43: 14,3 | S43: 17,3 | T43: 19,3 | U43: 23,3 | V43: 26,3 | AB43: enrique_espin | AC43: https://www.instagram.com/enrique_espin_cosme?igsh=MWNmN3hjOTgwbzB6OQ== | AD43: 28,3 | AE43: 30,3
...

Sheet Apr
B2: © Imperium Agency - All rights reserved. Do not share, copy, reproduce or sell any part of this document unless you have written permission from Imperium Labs LTD. All infringements will be prosecuted. If you are the personal owner of the Imperium Labs LTD End User License then you may use it for your own use but not for any other purpose.
C4: Stage | D4: Prospects | F4: Overall | G4: Conversion % | I4: Stage | J4: Conversion %
C5: (A) | D5: =COUNTIF(B13:B1000, "<>") -> 712 | F5: MSR | G5: =D6/D5 -> 0 | I5: A > MS | J5: =D6/D5 -> 0 | O5: Requests | P5: Accepted | Q5: CAR%
C6: (MS) | D6: =COUNTIF(K13:K1000, "YES") -> 0 | F6: PRR | G6: =D7/D5 -> 0.11657303 | I6: MS > B | J6: =D7/D6 -> #DIV/0! | Q6: =P6/O6 -> #DIV/0!
C7: (B) | D7: =COUNTIF(N13:N1000, "<>") -> 83 | F7: CSR | G7: =D8/D5 -> 0.054775281 | I7: B > C | J7: =D8/D7 -> 0.46987952
C8: (C) | D8: =COUNTIF(AB13:AB1000, "<>") -> 39 | F8: ABR | G8: =D9/D5 -> 0.029494382 | I8: C > D | J8: =D9/D8 -> 0.53846154
C9: (D) | D9: =COUNTIF(AP13:AP1000, "<>") -> 21
B11: To make a copy go file > make a copy
B12: Name (Initiate) (A) | C12: Profile Link | D12: Date Initiated | E12: 1A | F12: Notes | K12: Media Seen (MS) | N12: Name (Engaged) (B) | O12: Profile Link | P12: Date Engaged | Q12: 1B | R12: 2B | S12: 3B | T12: 4B | U12: 5B | V12: 6B | W12: 7B | X12: 8B | Y12: Notes | AB12: Name (C) | AC12: Profile Link | AD12: Date (C) | AE12: 1C | AF12: 2C | AG12: 3C | AH12: 4C | AI12: 5C | AJ12: 6C | AK12: 7C | AL12: 8B | AM12: Notes | AP12: Name (D) | AQ12: Date (D) | AR12: Notes
B13: Devi Rodríguez | C13: https://www.instagram.com/devirodriguezoficial?igsh=NHduZXpucjNrbTU4 | D13: 3,4 | E13: 7,4 | N13: alvarito schz | O13: https://www.instagram.com/alvarito.schz?igsh=MW1jeHh1MXhzbXZtMA== | P13: 6,4 | AB13: alvarito schz | AC13: https://www.instagram.com/alvarito.schz?igsh=MW1jeHh1MXhzbXZtMA== | AD13: 6,4 | AP13: Alvaro schz | AQ13: 6,4
B14: loooopez | C14: https://www.instagram.com/l0ppezzz?igsh=MTU1ank4ZWxtazJ3 | D14: 3,4 | E14: 7,4 | N14: benjamin | O14: https://www.instagram.com/benjamin_lopez_pina?igsh=NWFzem8wN245dW8z | P14: 6,4 | AB14: benjamin | AC14: https://www.instagram.com/benjamin_lopez_pina?igsh=NWFzem8wN245dW8z | AD14: 6,4 | AP14: Adrian perez | AQ14: 6,4
B15: ingenio alex | C15: https://www.instagram.com/ingenioalex?igsh=MWE0MHJxMmY2aG1zZA== | D15: 3,4 | E15: 7,4 | N15: adrian | O15: https://www.instagram.com/adrian_spartanov?igsh=MTg3Z3dyaXRmdnZxbg== | P15: 6,4 | AB15: adrian | AC15: https://www.instagram.com/adrian_spartanov?igsh=MTg3Z3dyaXRmdnZxbg== | AD15: 6,4 | AP15: Benjamin lopez | AQ15: 6,4
B16: franciscoalvarez | C16: https://www.instagram.com/franciscoalvarezbrandan?igsh=NzF2OTlidHk2cHh5 | D16: 6,4 | E16: 7,4 | N16: lili life | O16: https://www.instagram.com/lili.lifecoach?igsh=ZjJyMWdlZDVvYm9s | P16: 7,4 | AB16: ruben | AC16: https://www.instagram.com/rubenalmunia7?igsh=bDZxcmw1cXNybzE2 | AD16: 7,4 | AE16: 9,4 | AF16: 10,4 | AG16: Fup 20 | AH16: 21,4 | AP16: Tania | AQ16: 8,4
B17: luisoso | C17: https://www.instagram.com/luisosoriomaster?igsh=dnY4czR5bWgxMnBh | D17: 6,4 | E17: 7,4 | N17: timicaela | O17: https://www.instagram.com/tlmicaela?igsh=ZGwyM2lyMms3Mmo5 | P17: 7,4 | Q17: 8,4 | R17: 9,4 | S17: 10,4 | T17: Obj | U17: fup jun | AB17: tanuka | AC17: https://www.instagram.com/tanuka1982?igsh=eGE0M200YW92cW51 | AD17: 6,4 | AP17: luciano | AQ17: 8,4
B18: nilgnz | C18: https://www.instagram.com/nilgnzlz_?igsh=djdiZTFoOTg1eXl5 | D18: 6,4 | E18: 7,4 | N18: ruben | O18: https://www.instagram.com/rubenalmunia7?igsh=bDZxcmw1cXNybzE2 | P18: 7,4 | AB18: lili life | AC18: https://www.instagram.com/lili.lifecoach?igsh=ZjJyMWdlZDVvYm9s | AD18: 8,4 | AE18: 9,4 | AF18: 10,4 | AG18: 11,4 | AH18: Fup mar | AI18: 14,4 | AJ18: 18,4 | AP18: ivan Muñoz | AQ18: 11,4
B19: miroliveros | C19: https://www.instagram.com/miroliveros?igsh=MXY4bmYzbzZqeDY4aA== | D19: 6,4 | E19: 7,4 | N19: tanuka | O19: https://www.instagram.com/tanuka1982?igsh=eGE0M200YW92cW51 | P19: 6,4 | AB19: borja | AC19: https://www.instagram.com/borjainvirtiendo?igsh=b2x4b2JpcW81aTM0 | AD19: 7,4 | AE19: 9,4 | AF19: 10,4 | AG19: 11,4 | AH19: 12,4 | AI19: 13,4 | AJ19: 14,4 | AP19: Jordiroma | AQ19: 12,4
B20: idania | C20: https://www.instagram.com/idaniacohen?igsh=c3phN3FiMndxdGk3 | D20: 6,4 | E20: 7,4 | N20: irisaneas | O20: https://www.instagram.com/irisaneas_tantrart?igsh=MTNsaWowdzFrYm9hZQ== | P20: 8,4 | AB20: dow | AC20: https://www.instagram.com/dow_rmg?igsh=ZmljdWhtdnZpeWls | AD20: 7,4 | AE20: 9,4 | AF20: 10,4 | AG20: 11,4 | AH20: 12,4 | AI20: 14,4 | AP20: ingenio alex | AQ20: 14,4
B21: naturalezahisp | C21: https://www.instagram.com/naturalezahispania?igsh=MXEwcDBqb2tyeTM4cQ== | D21: 6,4 | E21: 7,4 | N21: josediaz | O21: https://www.instagram.com/josediazdelalmendrogutierrez?igsh=bDVvejhveDJ4eDk0 | P21: 7,4 | Q21: 8,4 | R21: 9,4 | AB21: vercher | AC21: https://www.instagram.com/vercher_dani?igsh=eWJuNG9lZWhoYnA2 | AD21: 7,4 | AE21: 9,4 | AF21: 10,4 | AG21: 11,4 | AH21: 12,4 | AI21: 14,4 | AP21: pedropertx | AQ21: 15,4
B22: maricruz | C22: https://www.instagram.com/maricruzalvarezdolado?igsh=cjU4djExbGEzbnRt | D22: 6,4 | E22: 7,4 | N22: anatorrico | O22: https://www.instagram.com/_anatorrico_?igsh=MXg0bzc0Mzk3OWlscQ== | P22: 7,4 | R22: 9,4 | S22: Fup lun | AB22: luciano | AC22: https://www.instagram.com/lucianodamario?igsh=MXYyYnVjMGp6bXNnYQ== | AD22: 7,4 | AP22: charlie | AQ22: 15,4
B23: pacomoreno | C23: https://www.instagram.com/pacomorenosilva?igsh=MTdqaTlxeTd1aGVreg== | D23: 6,4 | E23: 7,4 | N23: hector | O23: https://www.instagram.com/hectorroblesdiez?igsh=MTJhczF3Yjl2aThudA== | P23: 7,4 | Q23: 8,4 | AB23: fotoacruz | AC23: https://www.instagram.com/fotoacruzstudio?igsh=MWhudXp3emhudm4zbQ== | AD23: 7,4 | AE23: 9,4 | AF23: 10,4 | AG23: 11,4 | AP23: nazaret | AQ23: 18,4
B24: laura elarte | C24: https://www.instagram.com/laura_elartedelmasaje?igsh=MXR4cHoxNHp5a240ZA== | D24: 6,4 | E24: 7,4 | N24: mandalas | O24: https://www.instagram.com/mandalascreativos?igsh=aXppMmpvNmt2YXVv | P24: 8,4 | AB24: irisaneas | AC24: https://www.instagram.com/irisaneas_tantrart?igsh=MTNsaWowdzFrYm9hZQ== | AD24: 8,4 | AE24: 10,4 | AF24: 11,4 | AG24: 12,4 | AH24: 14,4 | AP24: andrea | AQ24: 20,4
B25: raul120 | C25: https://www.instagram.com/raul120__?igsh=MWh0dHplNzA1YjZhaQ== | D25: 6,4 | E25: 7,4 | N25: juanp m | O25: https://www.instagram.com/juanp.m.c85?igsh=cXpjem5qcjB3bHFk | P25: 8,4 | AB25: hector | AC25: https://www.instagram.com/hectorroblesdiez?igsh=MTJhczF3Yjl2aThudA== | AD25: 7,4 | AE25: 10,4 | AF25: 11,4 | AG25: 12,4 | AH25: 14,4 | AP25: Ruben | AQ25: 21,4
B26: enriquealcobe | C26: https://www.instagram.com/enriquealcobendas?igsh=c2RvMzQyNnlscm9s | D26: 6,4 | E26: 7,4 | N26: maricruz | O26: https://www.instagram.com/maricruzalvarezdolado?igsh=cjU4djExbGEzbnRt | P26: 6,4 | Q26: 9,4 | R26: 10,4 | S26: 11,4 | T26: 12,4 | U26: 18,4 | AB26: juanp m | AC26: https://www.instagram.com/juanp.m.c85?igsh=cXpjem5qcjB3bHFk | AD26: 8,4 | AE26: 10,4 | AF26: 11,4 | AG26: 12,4 | AH26: 14,4 | AP26: Rosa | AQ26: 22,4
B27: vidalespe | C27: https://www.instagram.com/vidalespe?igsh=MWFuYmtsdzhkb2p4dQ== | D27: 6,4 | E27: 7,4 | N27: laurent | O27: https://www.instagram.com/laurent_behot?igsh=MWJ4aTg3bDZtdDBqdA== | P27: 6,4 | Q27: 9,4 | R27: 10,4 | S27: 18,4 | T27: 20,4 | AB27: ingenio alex | AC27: https://www.instagram.com/ingenioalex?igsh=MWE0MHJxMmY2aG1zZA== | AD27: 3,4 | AP27: osvaldo | AQ27: 22,4
B28: ryandaw | C28: https://www.instagram.com/ryandawh?igsh=MXVxa3M1Njc5c3N3dA== | D28: 6,4 | E28: 7,4 | N28: borja | O28: https://www.instagram.com/borjainvirtiendo?igsh=b2x4b2JpcW81aTM0 | P28: 7,4 | AB28: jordiroma | AC28: https://www.instagram.com/jordiroma?igsh=aWUwOWQydWV0N21q | AD28: 7,4 | AE28: 10,4 | AP28: Pedro | AQ28: 27,4
B29: turubio | C29: https://www.instagram.com/turubiojosazulrs?igsh=MWM2bndzcnF3azFvdg== | D29: 6,4 | E29: 7,4 | N29: dow | O29: https://www.instagram.com/dow_rmg?igsh=ZmljdWhtdnZpeWls | P29: 7,4 | AB29: josediaz | AC29: https://www.instagram.com/josediazdelalmendrogutierrez?igsh=bDVvejhveDJ4eDk0 | AD29: 7,4 | AE29: 10,4 | AF29: 12,4 | AG29: 14,4 | AP29: rocio | AQ29: 27,4
B30: don david | C30: https://www.instagram.com/don_davidrg?igsh=MWNhYXljdnR3YmE0eA== | D30: 6,4 | E30: 7,4 | N30: vercher | O30: https://www.instagram.com/vercher_dani?igsh=eWJuNG9lZWhoYnA2 | P30: 7,4 | AB30: Ivanmunoz | AC30: https://www.instagram.com/ivanmunozhistorias?igsh=YmxtYjI4MDNlOGNv | AD30: 11,4 | AP30: sergiogar | AQ30: 27,4
B31: vicente alcobali | C31: https://www.instagram.com/vicente.alcobalisero?igsh=MTFnMDB2NTN6cHQwMg== | D31: 6,4 | E31: 7,4 | N31: luciano | O31: https://www.instagram.com/lucianodamario?igsh=MXYyYnVjMGp6bXNnYQ== | P31: 7,4 | AB31: evamaria | AC31: https://www.instagram.com/evamariabc?igsh=NG10dWg0aDZrdnd6 | AD31: 6,4 | AE31: 14,4 | AP31: hector | AQ31: 28,4
B32: juan4 | C32: https://www.instagram.com/juan4v?igsh=ZW1oMGtwM2Rvdmls | D32: 6,4 | E32: 7,4 | N32: errix | O32: https://www.instagram.com/erriixx1?igsh=MWR5cWFxbWs5bnVmZg== | P32: 6,4 | Q32: 9,4 | R32: 10,4 | S32: 18,4 | T32: 20,4 | AB32: toloalzina | AC32: https://www.instagram.com/toloalzina?igsh=d2RmY2Jtc3I4dWp1 | AD32: 9,4 | AE32: 14,4 | AF32: fup 1 may | AP32: nuriapalomo | AQ32: 29,4
B33: rosasuero | C33: https://www.instagram.com/rosasuero61?igsh=NGd4ejl6eWt0OHMx | D33: 6,4 | E33: 7,4 | N33: evamaria | O33: https://www.instagram.com/evamariabc?igsh=NG10dWg0aDZrdnd6 | P33: 6,4 | Q33: 9,4 | R33: 10,4 | AB33: tonibota | AC33: https://www.instagram.com/tonibota_pf?igsh=MWV0bXN2bjAzc2MwMQ== | AD33: 13,4 | AE33: 14,4 | AF33: 21,4 | AG33: 22,4 | AP33: motivandoa | AQ33: 28,4
B34: jotajj | C34: https://www.instagram.com/jotajjjvaras?igsh=MW1jdTlqNm1zaHBoYw== | D34: 6,4 | E34: 7,4 | N34: coachvirginia | O34: https://www.instagram.com/coachvirginiamartinez?igsh=MXdvcWMxeDJlaWswbg== | P34: 6,4 | Q34: 9,4 | R34: 10,4 | AB34: ingenioalex | AC34: https://www.instagram.com/ingenioalex?igsh=MWE0MHJxMmY2aG1zZA== | AD34: 14,4
B35: anam | C35: https://www.instagram.com/anam_maha?igsh=MTRlcXJjZHFidDV0aA== | D35: 6,4 | E35: 7,4 | N35: franbre | O35: https://www.instagram.com/franbrenesadi?igsh=MW03YnZoZWdhMjBjcg== | P35: 7,4 | Q35: 9,4 | R35: 10,4 | S35: 21,4 | T35: 22,4 | AB35: pedropertx | AC35: https://www.instagram.com/pedropertx?igsh=bTZlYXFkZTN3ZHE4 | AD35: 14,4
B36: josebarqueros | C36: https://www.instagram.com/josebarqueros?igsh=OG91N3dtbjRpYWw4 | D36: 6,4 | E36: 7,4 | N36: jordiroma | O36: https://www.instagram.com/jordiroma?igsh=aWUwOWQydWV0N21q | P36: 7,4 | Q36: 9,4 | AB36: nazaret | AC36: https://www.instagram.com/nazaretcaminoalser?igsh=bW41MDh0Zzdqam81 | AD36: 14,4
B37: djhugo | C37: https://www.instagram.com/djhugo2026?igsh=c29jZWpzNjlxa2lh | D37: 6,4 | E37: 7,4 | N37: fotoacruz | O37: https://www.instagram.com/fotoacruzstudio?igsh=MWhudXp3emhudm4zbQ== | P37: 7,4 | AB37: charlieun | AC37: https://www.instagram.com/charlieunderuno?igsh=MXpvbmZ5aGhiMjRm | AD37: 15,4
B38: sol jimenez | C38: https://www.instagram.com/sol_jimenezrozo?igsh=amJyMXRnenJzdXk2 | D38: 6,4 | E38: 7,4 | N38: ingenio alex | O38: https://www.instagram.com/ingenioalex?igsh=MWE0MHJxMmY2aG1zZA== | P38: 3,4 | AB38: yassin | AC38: https://www.instagram.com/its.yasin_?igsh=MXM0YWt2cTh1anNqdQ== | AD38: 17,4 | AE38: 21,4 | AF38: 22,4 | AG38: 23,4
B39: fabrizio | C39: https://www.instagram.com/fabrizio_del_d?igsh=bG56ZDg5b215eGFv | D39: 6,4 | E39: 7,4 | N39: oier | O39: https://www.instagram.com/oier_e.bengoetxea?igsh=MThkNnByZDdxd3RyOQ== | P39: 8,4 | Q39: 10,4 | R39: 11,4 | S39: 18,4 | T39: 20,4 | U39: 21,4 | V39: 22,4 | W39: 27,4 | AB39: Andrea Petrelli | AC39: https://www.instagram.com/petrellii?igsh=cmcwdTUxazNibzNz | AD39: 20,4
B40: malenia | C40: https://www.instagram.com/malenisaludybienestar?igsh=MXZpZmFqa3J0eWpiYw== | D40: 6,4 | E40: 7,4 | N40: jenite | O40: https://www.instagram.com/jenitejedor?igsh=MWV3NXU3b3U0NHh1Ng== | P40: 8,4 | Q40: 10,4 | R40: 11,4 | S40: 18,4 | T40: 20,4 | U40: 21,4 | V40: 22,4 | AB40: hector milbatallas | AC40: https://www.instagram.com/hector_milbatallas?igsh=NGtmM3E0ZmVuNTA2 | AD40: 20,4 | AE40: 21,4 | AF40: 22,4 | AG40: 23,4
B41: oscarcano | C41: https://www.instagram.com/oscarcano_abogado?igsh=MTR0NXQ0NTVpM3oyMA== | D41: 6,4 | E41: 7,4 | N41: toloalzina | O41: https://www.instagram.com/toloalzina?igsh=d2RmY2Jtc3I4dWp1 | P41: 9,4 | Q41: 10,4 | R41: 11,4 | AB41: gongone | AC41: https://www.instagram.com/gongone10?igsh=MTJhZjhldXo5cnd2Ng== | AD41: 10,4 | AE41: 22,4 | AF41: 23,4
B42: baeza | C42: https://www.instagram.com/baezatrotamundos?igsh=MW5sMG41eHJxdnh2cA== | D42: 6,4 | E42: 7,4 | N42: david vina | O42: https://www.instagram.com/david_vinagreperez?igsh=MmhyYWtpcXZuZzFi | P42: 9,4 | Q42: 10,4 | R42: 11,4 | S42: 18,4 | T42: 20,4 | U42: 21,4 | V42: 22,4 | W42: 23,4 | X42: 27,4 | AB42: Rosa | AC42: https://www.instagram.com/rosadomarco_?igsh=MW9kaDBkbXlyZWpiNA== | AD42: 22,4
B43: laurent | C43: https://www.instagram.com/laurent_behot?igsh=MWJ4aTg3bDZtdDBqdA== | D43: 6,4 | E43: 7,4 | N43: diana torres | O43: https://www.instagram.com/diana.torres_c?igsh=MWFmdWcwcDkyeGlmMw== | P43: 9,4 | Q43: 10,4 | R43: 11,4 | S43: fup vie | T43: 23,4 | U43: 27,4 | AB43: luis gonzalez | AC43: https://www.instagram.com/luis_gonzalez.go?igsh=MW44bTAzbWk5N2gyZQ== | AD43: 21,4 | AE43: 27,4
...

Sheet May
B2: © Imperium Agency - All rights reserved. Do not share, copy, reproduce or sell any part of this document unless you have written permission from Imperium Labs LTD. All infringements will be prosecuted. If you are the personal owner of the Imperium Labs LTD End User License then you may use it for your own use but not for any other purpose.
C4: Stage | D4: Prospects | F4: Overall | G4: Conversion % | I4: Stage | J4: Conversion %
C5: (A) | D5: =COUNTIF(B13:B1000, "<>") -> 0 | F5: MSR | G5: =D6/D5 -> #DIV/0! | I5: A > MS | J5: =D6/D5 -> #DIV/0! | O5: Requests | P5: Accepted | Q5: CAR%
C6: (MS) | D6: =COUNTIF(K13:K1000, "YES") -> 0 | F6: PRR | G6: =D7/D5 -> #DIV/0! | I6: MS > B | J6: =D7/D6 -> #DIV/0! | Q6: =P6/O6 -> #DIV/0!
C7: (B) | D7: =COUNTIF(N13:N1000, "<>") -> 0 | F7: CSR | G7: =D8/D5 -> #DIV/0! | I7: B > C | J7: =D8/D7 -> #DIV/0!
C8: (C) | D8: =COUNTIF(AB13:AB1000, "<>") -> 0 | F8: ABR | G8: =D9/D5 -> #DIV/0! | I8: C > D | J8: =D9/D8 -> #DIV/0!
C9: (D) | D9: =COUNTIF(AP13:AP1000, "<>") -> 0
B11: To make a copy go file > make a copy
B12: Name (Initiate) (A) | C12: Profile Link | D12: Date Initiated | E12: 1A | F12: Notes | K12: Media Seen (MS) | N12: Name (Engaged) (B) | O12: Profile Link | P12: Date Engaged | Q12: 1B | R12: 2B | S12: 3B | T12: 4B | U12: 5B | V12: 6B | W12: 7B | X12: 8B | Y12: Notes | AB12: Name (C) | AC12: Profile Link | AD12: Date (C) | AE12: 1C | AF12: 2C | AG12: 3C | AH12: 4C | AI12: 5C | AJ12: 6C | AK12: 7C | AL12: 8B | AM12: Notes | AP12: Name (D) | AQ12: Date (D) | AR12: Notes

Sheet Jun
B2: © Imperium Agency - All rights reserved. Do not share, copy, reproduce or sell any part of this document unless you have written permission from Imperium Labs LTD. All infringements will be prosecuted. If you are the personal owner of the Imperium Labs LTD End User License then you may use it for your own use but not for any other purpose.
C4: Stage | D4: Prospects | F4: Overall | G4: Conversion % | I4: Stage | J4: Conversion %
C5: (A) | D5: =COUNTIF(B13:B1000, "<>") -> 0 | F5: MSR | G5: =D6/D5 -> #DIV/0! | I5: A > MS | J5: =D6/D5 -> #DIV/0! | O5: Requests | P5: Accepted | Q5: CAR%
C6: (MS) | D6: =COUNTIF(K13:K1000, "YES") -> 0 | F6: PRR | G6: =D7/D5 -> #DIV/0! | I6: MS > B | J6: =D7/D6 -> #DIV/0! | Q6: =P6/O6 -> #DIV/0!
C7: (B) | D7: =COUNTIF(N13:N1000, "<>") -> 0 | F7: CSR | G7: =D8/D5 -> #DIV/0! | I7: B > C | J7: =D8/D7 -> #DIV/0!
C8: (C) | D8: =COUNTIF(AB13:AB1000, "<>") -> 0 | F8: ABR | G8: =D9/D5 -> #DIV/0! | I8: C > D | J8: =D9/D8 -> #DIV/0!
C9: (D) | D9: =COUNTIF(AP13:AP1000, "<>") -> 0
B11: To make a copy go file > make a copy
B12: Name (Initiate) (A) | C12: Profile Link | D12: Date Initiated | E12: 1A | F12: Notes | K12: Media Seen (MS) | N12: Name (Engaged) (B) | O12: Profile Link | P12: Date Engaged | Q12: 1B | R12: 2B | S12: 3B | T12: 4B | U12: 5B | V12: 6B | W12: 7B | X12: 8B | Y12: Notes | AB12: Name (C) | AC12: Profile Link | AD12: Date (C) | AE12: 1C | AF12: 2C | AG12: 3C | AH12: 4C | AI12: 5C | AJ12: 6C | AK12: 7C | AL12: 8B | AM12: Notes | AP12: Name (D) | AQ12: Date (D) | AR12: Notes

Sheet Jul
B2: © Imperium Agency - All rights reserved. Do not share, copy, reproduce or sell any part of this document unless you have written permission from Imperium Labs LTD. All infringements will be prosecuted. If you are the personal owner of the Imperium Labs LTD End User License then you may use it for your own use but not for any other purpose.
C4: Stage | D4: Prospects | F4: Overall | G4: Conversion % | I4: Stage | J4: Conversion %
C5: (A) | D5: =COUNTIF(B13:B1000, "<>") -> 0 | F5: MSR | G5: =D6/D5 -> #DIV/0! | I5: A > MS | J5: =D6/D5 -> #DIV/0! | O5: Requests | P5: Accepted | Q5: CAR%
